Traceback (most recent call last):
  File "/home/titan/anaconda3/lib/python3.10/site-packages/botasaurus/decorators.py", line 593, in run_task
    result = func(reqs, data)
  File "/home/titan/Desktop/Python/ForMarketing/google-maps-scraper/src/scraper.py", line 113, in scrape_place
    data = extract_data(app_initialization_state, link)
  File "/home/titan/Desktop/Python/ForMarketing/google-maps-scraper/src/extract_data.py", line 579, in extract_data
    data = parse(input_str)
  File "/home/titan/Desktop/Python/ForMarketing/google-maps-scraper/src/extract_data.py", line 436, in parse
    input_string = json.loads(data)[3][6]  # Replace with actual input
IndexError: list index out of range

During handling of the above exception, another exception occurred:

Traceback (most recent call last):
  File "/home/titan/anaconda3/lib/python3.10/site-packages/botasaurus/decorators.py", line 593, in run_task
    result = func(reqs, data)
  File "/home/titan/Desktop/Python/ForMarketing/google-maps-scraper/src/scraper.py", line 113, in scrape_place
    data = extract_data(app_initialization_state, link)
  File "/home/titan/Desktop/Python/ForMarketing/google-maps-scraper/src/extract_data.py", line 579, in extract_data
    data = parse(input_str)
  File "/home/titan/Desktop/Python/ForMarketing/google-maps-scraper/src/extract_data.py", line 436, in parse
    input_string = json.loads(data)[3][6]  # Replace with actual input
IndexError: list index out of range

During handling of the above exception, another exception occurred:

Traceback (most recent call last):
  File "/home/titan/anaconda3/lib/python3.10/site-packages/botasaurus/decorators.py", line 593, in run_task
    result = func(reqs, data)
  File "/home/titan/Desktop/Python/ForMarketing/google-maps-scraper/src/scraper.py", line 113, in scrape_place
    data = extract_data(app_initialization_state, link)
  File "/home/titan/Desktop/Python/ForMarketing/google-maps-scraper/src/extract_data.py", line 579, in extract_data
    data = parse(input_str)
  File "/home/titan/Desktop/Python/ForMarketing/google-maps-scraper/src/extract_data.py", line 436, in parse
    input_string = json.loads(data)[3][6]  # Replace with actual input
IndexError: list index out of range

During handling of the above exception, another exception occurred:

Traceback (most recent call last):
  File "/home/titan/anaconda3/lib/python3.10/site-packages/botasaurus/decorators.py", line 593, in run_task
    result = func(reqs, data)
  File "/home/titan/Desktop/Python/ForMarketing/google-maps-scraper/src/scraper.py", line 113, in scrape_place
    data = extract_data(app_initialization_state, link)
  File "/home/titan/Desktop/Python/ForMarketing/google-maps-scraper/src/extract_data.py", line 579, in extract_data
    data = parse(input_str)
  File "/home/titan/Desktop/Python/ForMarketing/google-maps-scraper/src/extract_data.py", line 436, in parse
    input_string = json.loads(data)[3][6]  # Replace with actual input
IndexError: list index out of range

During handling of the above exception, another exception occurred:

Traceback (most recent call last):
  File "/home/titan/anaconda3/lib/python3.10/site-packages/urllib3/response.py", line 761, in _update_chunk_length
    self.chunk_left = int(line, 16)
ValueError: invalid literal for int() with base 16: b''

During handling of the above exception, another exception occurred:

Traceback (most recent call last):
  File "/home/titan/anaconda3/lib/python3.10/site-packages/urllib3/response.py", line 444, in _error_catcher
    yield
  File "/home/titan/anaconda3/lib/python3.10/site-packages/urllib3/response.py", line 828, in read_chunked
    self._update_chunk_length()
  File "/home/titan/anaconda3/lib/python3.10/site-packages/urllib3/response.py", line 765, in _update_chunk_length
    raise InvalidChunkLength(self, line)
urllib3.exceptions.InvalidChunkLength: InvalidChunkLength(got length b'', 0 bytes read)

During handling of the above exception, another exception occurred:

Traceback (most recent call last):
  File "/home/titan/.local/lib/python3.10/site-packages/requests/models.py", line 816, in generate
    yield from self.raw.stream(chunk_size, decode_content=True)
  File "/home/titan/anaconda3/lib/python3.10/site-packages/urllib3/response.py", line 624, in stream
    for line in self.read_chunked(amt, decode_content=decode_content):
  File "/home/titan/anaconda3/lib/python3.10/site-packages/urllib3/response.py", line 816, in read_chunked
    with self._error_catcher():
  File "/home/titan/anaconda3/lib/python3.10/contextlib.py", line 153, in __exit__
    self.gen.throw(typ, value, traceback)
  File "/home/titan/anaconda3/lib/python3.10/site-packages/urllib3/response.py", line 461, in _error_catcher
    raise ProtocolError("Connection broken: %r" % e, e)
urllib3.exceptions.ProtocolError: ("Connection broken: InvalidChunkLength(got length b'', 0 bytes read)", InvalidChunkLength(got length b'', 0 bytes read))

During handling of the above exception, another exception occurred:

Traceback (most recent call last):
  File "/home/titan/anaconda3/lib/python3.10/site-packages/botasaurus/decorators.py", line 593, in run_task
    result = func(reqs, data)
  File "/home/titan/Desktop/Python/ForMarketing/google-maps-scraper/src/scraper.py", line 105, in scrape_place
    html =  requests.get(link,cookies=cookies,).text
  File "/home/titan/.local/lib/python3.10/site-packages/requests/sessions.py", line 600, in get
    return self.request("GET", url, **kwargs)
  File "/home/titan/anaconda3/lib/python3.10/site-packages/cloudscraper/__init__.py", line 259, in request
    self.perform_request(method, url, *args, **kwargs)
  File "/home/titan/anaconda3/lib/python3.10/site-packages/cloudscraper/__init__.py", line 192, in perform_request
    return super(CloudScraper, self).request(method, url, *args, **kwargs)
  File "/home/titan/.local/lib/python3.10/site-packages/requests/sessions.py", line 587, in request
    resp = self.send(prep, **send_kwargs)
  File "/home/titan/.local/lib/python3.10/site-packages/requests/sessions.py", line 745, in send
    r.content
  File "/home/titan/.local/lib/python3.10/site-packages/requests/models.py", line 899, in content
    self._content = b"".join(self.iter_content(CONTENT_CHUNK_SIZE)) or b""
  File "/home/titan/.local/lib/python3.10/site-packages/requests/models.py", line 818, in generate
    raise ChunkedEncodingError(e)
requests.exceptions.ChunkedEncodingError: ("Connection broken: InvalidChunkLength(got length b'', 0 bytes read)", InvalidChunkLength(got length b'', 0 bytes read))

During handling of the above exception, another exception occurred:

Traceback (most recent call last):
  File "/home/titan/anaconda3/lib/python3.10/site-packages/botasaurus/decorators.py", line 593, in run_task
    result = func(reqs, data)
  File "/home/titan/Desktop/Python/ForMarketing/google-maps-scraper/src/scraper.py", line 113, in scrape_place
    data = extract_data(app_initialization_state, link)
  File "/home/titan/Desktop/Python/ForMarketing/google-maps-scraper/src/extract_data.py", line 579, in extract_data
    data = parse(input_str)
  File "/home/titan/Desktop/Python/ForMarketing/google-maps-scraper/src/extract_data.py", line 436, in parse
    input_string = json.loads(data)[3][6]  # Replace with actual input
IndexError: list index out of range
