Traceback (most recent call last):
  File "/home/titan/anaconda3/lib/python3.10/site-packages/botasaurus/decorators.py", line 593, in run_task
    result = func(reqs, data)
  File "/home/titan/Desktop/Python/ForMarketing/google-maps-scraper/src/scraper.py", line 108, in scrape_place
    html =  requests.get(link,cookies=cookies,).text
  File "/home/titan/Desktop/Python/ForMarketing/google-maps-scraper/requests/sessions.py", line 602, in get
    return self.request("GET", url, **kwargs)
  File "/home/titan/anaconda3/lib/python3.10/site-packages/cloudscraper/__init__.py", line 259, in request
    self.perform_request(method, url, *args, **kwargs)
  File "/home/titan/anaconda3/lib/python3.10/site-packages/cloudscraper/__init__.py", line 192, in perform_request
    return super(CloudScraper, self).request(method, url, *args, **kwargs)
  File "/home/titan/Desktop/Python/ForMarketing/google-maps-scraper/requests/sessions.py", line 575, in request
    prep = self.prepare_request(req)
  File "/home/titan/Desktop/Python/ForMarketing/google-maps-scraper/requests/sessions.py", line 486, in prepare_request
    p.prepare(
  File "/home/titan/Desktop/Python/ForMarketing/google-maps-scraper/requests/models.py", line 368, in prepare
    self.prepare_url(url, params)
  File "/home/titan/Desktop/Python/ForMarketing/google-maps-scraper/requests/models.py", line 439, in prepare_url
    raise MissingSchema(
requests.exceptions.MissingSchema: Invalid URL 'Not Found': No scheme supplied. Perhaps you meant https://Not Found?

During handling of the above exception, another exception occurred:

Traceback (most recent call last):
  File "/home/titan/anaconda3/lib/python3.10/site-packages/botasaurus/decorators.py", line 593, in run_task
    result = func(reqs, data)
  File "/home/titan/Desktop/Python/ForMarketing/google-maps-scraper/src/scraper.py", line 108, in scrape_place
    html =  requests.get(link,cookies=cookies,).text
  File "/home/titan/Desktop/Python/ForMarketing/google-maps-scraper/requests/sessions.py", line 602, in get
    return self.request("GET", url, **kwargs)
  File "/home/titan/anaconda3/lib/python3.10/site-packages/cloudscraper/__init__.py", line 259, in request
    self.perform_request(method, url, *args, **kwargs)
  File "/home/titan/anaconda3/lib/python3.10/site-packages/cloudscraper/__init__.py", line 192, in perform_request
    return super(CloudScraper, self).request(method, url, *args, **kwargs)
  File "/home/titan/Desktop/Python/ForMarketing/google-maps-scraper/requests/sessions.py", line 575, in request
    prep = self.prepare_request(req)
  File "/home/titan/Desktop/Python/ForMarketing/google-maps-scraper/requests/sessions.py", line 486, in prepare_request
    p.prepare(
  File "/home/titan/Desktop/Python/ForMarketing/google-maps-scraper/requests/models.py", line 368, in prepare
    self.prepare_url(url, params)
  File "/home/titan/Desktop/Python/ForMarketing/google-maps-scraper/requests/models.py", line 439, in prepare_url
    raise MissingSchema(
requests.exceptions.MissingSchema: Invalid URL 'Not Found': No scheme supplied. Perhaps you meant https://Not Found?

During handling of the above exception, another exception occurred:

Traceback (most recent call last):
  File "/home/titan/anaconda3/lib/python3.10/site-packages/botasaurus/decorators.py", line 593, in run_task
    result = func(reqs, data)
  File "/home/titan/Desktop/Python/ForMarketing/google-maps-scraper/src/scraper.py", line 108, in scrape_place
    html =  requests.get(link,cookies=cookies,).text
  File "/home/titan/Desktop/Python/ForMarketing/google-maps-scraper/requests/sessions.py", line 602, in get
    return self.request("GET", url, **kwargs)
  File "/home/titan/anaconda3/lib/python3.10/site-packages/cloudscraper/__init__.py", line 259, in request
    self.perform_request(method, url, *args, **kwargs)
  File "/home/titan/anaconda3/lib/python3.10/site-packages/cloudscraper/__init__.py", line 192, in perform_request
    return super(CloudScraper, self).request(method, url, *args, **kwargs)
  File "/home/titan/Desktop/Python/ForMarketing/google-maps-scraper/requests/sessions.py", line 575, in request
    prep = self.prepare_request(req)
  File "/home/titan/Desktop/Python/ForMarketing/google-maps-scraper/requests/sessions.py", line 486, in prepare_request
    p.prepare(
  File "/home/titan/Desktop/Python/ForMarketing/google-maps-scraper/requests/models.py", line 368, in prepare
    self.prepare_url(url, params)
  File "/home/titan/Desktop/Python/ForMarketing/google-maps-scraper/requests/models.py", line 439, in prepare_url
    raise MissingSchema(
requests.exceptions.MissingSchema: Invalid URL 'Not Found': No scheme supplied. Perhaps you meant https://Not Found?

During handling of the above exception, another exception occurred:

Traceback (most recent call last):
  File "/home/titan/anaconda3/lib/python3.10/site-packages/botasaurus/decorators.py", line 593, in run_task
    result = func(reqs, data)
  File "/home/titan/Desktop/Python/ForMarketing/google-maps-scraper/src/scraper.py", line 108, in scrape_place
    html =  requests.get(link,cookies=cookies,).text
  File "/home/titan/Desktop/Python/ForMarketing/google-maps-scraper/requests/sessions.py", line 602, in get
    return self.request("GET", url, **kwargs)
  File "/home/titan/anaconda3/lib/python3.10/site-packages/cloudscraper/__init__.py", line 259, in request
    self.perform_request(method, url, *args, **kwargs)
  File "/home/titan/anaconda3/lib/python3.10/site-packages/cloudscraper/__init__.py", line 192, in perform_request
    return super(CloudScraper, self).request(method, url, *args, **kwargs)
  File "/home/titan/Desktop/Python/ForMarketing/google-maps-scraper/requests/sessions.py", line 575, in request
    prep = self.prepare_request(req)
  File "/home/titan/Desktop/Python/ForMarketing/google-maps-scraper/requests/sessions.py", line 486, in prepare_request
    p.prepare(
  File "/home/titan/Desktop/Python/ForMarketing/google-maps-scraper/requests/models.py", line 368, in prepare
    self.prepare_url(url, params)
  File "/home/titan/Desktop/Python/ForMarketing/google-maps-scraper/requests/models.py", line 439, in prepare_url
    raise MissingSchema(
requests.exceptions.MissingSchema: Invalid URL 'Not Found': No scheme supplied. Perhaps you meant https://Not Found?

During handling of the above exception, another exception occurred:

Traceback (most recent call last):
  File "/home/titan/anaconda3/lib/python3.10/site-packages/botasaurus/decorators.py", line 593, in run_task
    result = func(reqs, data)
  File "/home/titan/Desktop/Python/ForMarketing/google-maps-scraper/src/scraper.py", line 108, in scrape_place
    html =  requests.get(link,cookies=cookies,).text
  File "/home/titan/Desktop/Python/ForMarketing/google-maps-scraper/requests/sessions.py", line 602, in get
    return self.request("GET", url, **kwargs)
  File "/home/titan/anaconda3/lib/python3.10/site-packages/cloudscraper/__init__.py", line 259, in request
    self.perform_request(method, url, *args, **kwargs)
  File "/home/titan/anaconda3/lib/python3.10/site-packages/cloudscraper/__init__.py", line 192, in perform_request
    return super(CloudScraper, self).request(method, url, *args, **kwargs)
  File "/home/titan/Desktop/Python/ForMarketing/google-maps-scraper/requests/sessions.py", line 575, in request
    prep = self.prepare_request(req)
  File "/home/titan/Desktop/Python/ForMarketing/google-maps-scraper/requests/sessions.py", line 486, in prepare_request
    p.prepare(
  File "/home/titan/Desktop/Python/ForMarketing/google-maps-scraper/requests/models.py", line 368, in prepare
    self.prepare_url(url, params)
  File "/home/titan/Desktop/Python/ForMarketing/google-maps-scraper/requests/models.py", line 439, in prepare_url
    raise MissingSchema(
requests.exceptions.MissingSchema: Invalid URL 'Not Found': No scheme supplied. Perhaps you meant https://Not Found?

During handling of the above exception, another exception occurred:

Traceback (most recent call last):
  File "/home/titan/anaconda3/lib/python3.10/site-packages/botasaurus/decorators.py", line 593, in run_task
    result = func(reqs, data)
  File "/home/titan/Desktop/Python/ForMarketing/google-maps-scraper/src/scraper.py", line 108, in scrape_place
    html =  requests.get(link,cookies=cookies,).text
  File "/home/titan/Desktop/Python/ForMarketing/google-maps-scraper/requests/sessions.py", line 602, in get
    return self.request("GET", url, **kwargs)
  File "/home/titan/anaconda3/lib/python3.10/site-packages/cloudscraper/__init__.py", line 259, in request
    self.perform_request(method, url, *args, **kwargs)
  File "/home/titan/anaconda3/lib/python3.10/site-packages/cloudscraper/__init__.py", line 192, in perform_request
    return super(CloudScraper, self).request(method, url, *args, **kwargs)
  File "/home/titan/Desktop/Python/ForMarketing/google-maps-scraper/requests/sessions.py", line 575, in request
    prep = self.prepare_request(req)
  File "/home/titan/Desktop/Python/ForMarketing/google-maps-scraper/requests/sessions.py", line 486, in prepare_request
    p.prepare(
  File "/home/titan/Desktop/Python/ForMarketing/google-maps-scraper/requests/models.py", line 368, in prepare
    self.prepare_url(url, params)
  File "/home/titan/Desktop/Python/ForMarketing/google-maps-scraper/requests/models.py", line 439, in prepare_url
    raise MissingSchema(
requests.exceptions.MissingSchema: Invalid URL 'Not Found': No scheme supplied. Perhaps you meant https://Not Found?
